2019-07-21 00:42:17,929 - [simpleLogger] - [ERROR] - views.save - Traceback (most recent call last):
  File "/Users/ymbp/Dev/workspace_py/PyLab/libManager/views.py", line 40, in save
    bk_ISBN=isbn,bk_material=material)
  File "/Library/Frameworks/Python.framework/Versions/3.6/lib/python3.6/site-packages/django/db/models/base.py", line 467, in __init__
    _setattr(self, field.name, rel_obj)
  File "/Library/Frameworks/Python.framework/Versions/3.6/lib/python3.6/site-packages/django/db/models/fields/related_descriptors.py", line 210, in __set__
    self.field.remote_field.model._meta.object_name,
ValueError: Cannot assign "'南海出版公司'": "Book.bk_press" must be a "PublishHouse" instance.

2019-07-21 00:46:07,426 - [simpleLogger] - [ERROR] - views.save - Traceback (most recent call last):
  File "/Users/ymbp/Dev/workspace_py/PyLab/libManager/views.py", line 40, in save
    bk_ISBN=isbn,bk_material=material)
  File "/Library/Frameworks/Python.framework/Versions/3.6/lib/python3.6/site-packages/django/db/models/base.py", line 467, in __init__
    _setattr(self, field.name, rel_obj)
  File "/Library/Frameworks/Python.framework/Versions/3.6/lib/python3.6/site-packages/django/db/models/fields/related_descriptors.py", line 210, in __set__
    self.field.remote_field.model._meta.object_name,
ValueError: Cannot assign "'南海出版公司'": "Book.bk_press" must be a "PublishHouse" instance.

2019-07-21 00:52:37,749 - [simpleLogger] - [ERROR] - views.save - Traceback (most recent call last):
  File "/Users/ymbp/Dev/workspace_py/PyLab/libManager/views.py", line 40, in save
    bk_ISBN=isbn, bk_material=material)
  File "/Library/Frameworks/Python.framework/Versions/3.6/lib/python3.6/site-packages/django/db/models/base.py", line 467, in __init__
    _setattr(self, field.name, rel_obj)
  File "/Library/Frameworks/Python.framework/Versions/3.6/lib/python3.6/site-packages/django/db/models/fields/related_descriptors.py", line 210, in __set__
    self.field.remote_field.model._meta.object_name,
ValueError: Cannot assign "'南海出版公司'": "Book.bk_press" must be a "PublishHouse" instance.

2019-07-21 00:59:17,785 - [simpleLogger] - [ERROR] - views.save - Traceback (most recent call last):
  File "/Users/ymbp/Dev/workspace_py/PyLab/libManager/views.py", line 41, in save
    bk_ISBN=isbn, bk_material=material)
  File "/Library/Frameworks/Python.framework/Versions/3.6/lib/python3.6/site-packages/django/db/models/base.py", line 485, in __init__
    raise TypeError("'%s' is an invalid keyword argument for this function" % kwarg)
TypeError: 'subtitle' is an invalid keyword argument for this function

2019-07-21 01:04:33,064 - [simpleLogger] - [ERROR] - views.save - Traceback (most recent call last):
  File "/Users/ymbp/Dev/workspace_py/PyLab/libManager/views.py", line 40, in save
    bk_ISBN=isbn, bk_material=material)
  File "/Library/Frameworks/Python.framework/Versions/3.6/lib/python3.6/site-packages/django/db/models/base.py", line 485, in __init__
    raise TypeError("'%s' is an invalid keyword argument for this function" % kwarg)
TypeError: 'bk_press' is an invalid keyword argument for this function

2019-07-21 01:05:05,733 - [simpleLogger] - [ERROR] - views.save - Traceback (most recent call last):
  File "/Users/ymbp/Dev/workspace_py/PyLab/libManager/views.py", line 40, in save
    bk_ISBN=isbn, bk_material=material)
  File "/Library/Frameworks/Python.framework/Versions/3.6/lib/python3.6/site-packages/django/db/models/base.py", line 485, in __init__
    raise TypeError("'%s' is an invalid keyword argument for this function" % kwarg)
TypeError: 'bk_press' is an invalid keyword argument for this function

2019-07-21 01:05:35,328 - [simpleLogger] - [ERROR] - views.save - Traceback (most recent call last):
  File "/Library/Frameworks/Python.framework/Versions/3.6/lib/python3.6/site-packages/django/db/backends/mysql/base.py", line 71, in execute
    return self.cursor.execute(query, args)
  File "/Library/Frameworks/Python.framework/Versions/3.6/lib/python3.6/site-packages/MySQLdb/cursors.py", line 206, in execute
    res = self._query(query)
  File "/Library/Frameworks/Python.framework/Versions/3.6/lib/python3.6/site-packages/MySQLdb/cursors.py", line 312, in _query
    db.query(q)
  File "/Library/Frameworks/Python.framework/Versions/3.6/lib/python3.6/site-packages/MySQLdb/connections.py", line 224, in query
    _mysql.connection.query(self, query)
MySQLdb._exceptions.OperationalError: (1048, "Column 'bk_subtitle' cannot be null")

During handling of the above exception, another exception occurred:

Traceback (most recent call last):
  File "/Users/ymbp/Dev/workspace_py/PyLab/libManager/views.py", line 41, in save
    book.save()
  File "/Library/Frameworks/Python.framework/Versions/3.6/lib/python3.6/site-packages/django/db/models/base.py", line 718, in save
    force_update=force_update, update_fields=update_fields)
  File "/Library/Frameworks/Python.framework/Versions/3.6/lib/python3.6/site-packages/django/db/models/base.py", line 748, in save_base
    updated = self._save_table(raw, cls, force_insert, force_update, using, update_fields)
  File "/Library/Frameworks/Python.framework/Versions/3.6/lib/python3.6/site-packages/django/db/models/base.py", line 831, in _save_table
    result = self._do_insert(cls._base_manager, using, fields, update_pk, raw)
  File "/Library/Frameworks/Python.framework/Versions/3.6/lib/python3.6/site-packages/django/db/models/base.py", line 869, in _do_insert
    using=using, raw=raw)
  File "/Library/Frameworks/Python.framework/Versions/3.6/lib/python3.6/site-packages/django/db/models/manager.py", line 82, in manager_method
    return getattr(self.get_queryset(), name)(*args, **kwargs)
  File "/Library/Frameworks/Python.framework/Versions/3.6/lib/python3.6/site-packages/django/db/models/query.py", line 1136, in _insert
    return query.get_compiler(using=using).execute_sql(return_id)
  File "/Library/Frameworks/Python.framework/Versions/3.6/lib/python3.6/site-packages/django/db/models/sql/compiler.py", line 1289, in execute_sql
    cursor.execute(sql, params)
  File "/Library/Frameworks/Python.framework/Versions/3.6/lib/python3.6/site-packages/django/db/backends/utils.py", line 100, in execute
    return super().execute(sql, params)
  File "/Library/Frameworks/Python.framework/Versions/3.6/lib/python3.6/site-packages/django/db/backends/utils.py", line 68, in execute
    return self._execute_with_wrappers(sql, params, many=False, executor=self._execute)
  File "/Library/Frameworks/Python.framework/Versions/3.6/lib/python3.6/site-packages/django/db/backends/utils.py", line 77, in _execute_with_wrappers
    return executor(sql, params, many, context)
  File "/Library/Frameworks/Python.framework/Versions/3.6/lib/python3.6/site-packages/django/db/backends/utils.py", line 85, in _execute
    return self.cursor.execute(sql, params)
  File "/Library/Frameworks/Python.framework/Versions/3.6/lib/python3.6/site-packages/django/db/backends/mysql/base.py", line 76, in execute
    raise utils.IntegrityError(*tuple(e.args))
django.db.utils.IntegrityError: (1048, "Column 'bk_subtitle' cannot be null")

shiweixuns-MacBook-Pro:ymbp ~/Dev/workspace_py/PyLab$python manage.py makemigrations
Traceback (most recent call last):
  File "/Library/Frameworks/Python.framework/Versions/3.6/lib/python3.6/site-packages/django/db/utils.py", line 167, in ensure_defaults
    conn = self.databases[alias]
  File "/Library/Frameworks/Python.framework/Versions/3.6/lib/python3.6/site-packages/django/utils/functional.py", line 37, in __get__
    res = instance.__dict__[self.name] = self.func(instance)
  File "/Library/Frameworks/Python.framework/Versions/3.6/lib/python3.6/site-packages/django/db/utils.py", line 154, in databases
    if self._databases[DEFAULT_DB_ALIAS] == {}:
KeyError: 'default'

During handling of the above exception, another exception occurred:

Traceback (most recent call last):
  File "manage.py", line 15, in <module>
    execute_from_command_line(sys.argv)
  File "/Library/Frameworks/Python.framework/Versions/3.6/lib/python3.6/site-packages/django/core/management/__init__.py", line 381, in execute_from_command_line
    utility.execute()
  File "/Library/Frameworks/Python.framework/Versions/3.6/lib/python3.6/site-packages/django/core/management/__init__.py", line 357, in execute
    django.setup()
  File "/Library/Frameworks/Python.framework/Versions/3.6/lib/python3.6/site-packages/django/__init__.py", line 24, in setup
    apps.populate(settings.INSTALLED_APPS)
  File "/Library/Frameworks/Python.framework/Versions/3.6/lib/python3.6/site-packages/django/apps/registry.py", line 112, in populate
    app_config.import_models()
  File "/Library/Frameworks/Python.framework/Versions/3.6/lib/python3.6/site-packages/django/apps/config.py", line 198, in import_models
    self.models_module = import_module(models_module_name)
  File "/Library/Frameworks/Python.framework/Versions/3.6/lib/python3.6/importlib/__init__.py", line 126, in import_module
    return _bootstrap._gcd_import(name[level:], package, level)
  File "<frozen importlib._bootstrap>", line 994, in _gcd_import
  File "<frozen importlib._bootstrap>", line 971, in _find_and_load
  File "<frozen importlib._bootstrap>", line 955, in _find_and_load_unlocked
  File "<frozen importlib._bootstrap>", line 665, in _load_unlocked
  File "<frozen importlib._bootstrap_external>", line 678, in exec_module
  File "<frozen importlib._bootstrap>", line 219, in _call_with_frames_removed
  File "/Library/Frameworks/Python.framework/Versions/3.6/lib/python3.6/site-packages/django/contrib/auth/models.py", line 2, in <module>
    from django.contrib.auth.base_user import AbstractBaseUser, BaseUserManager
  File "/Library/Frameworks/Python.framework/Versions/3.6/lib/python3.6/site-packages/django/contrib/auth/base_user.py", line 47, in <module>
    class AbstractBaseUser(models.Model):
  File "/Library/Frameworks/Python.framework/Versions/3.6/lib/python3.6/site-packages/django/db/models/base.py", line 101, in __new__
    new_class.add_to_class('_meta', Options(meta, app_label))
  File "/Library/Frameworks/Python.framework/Versions/3.6/lib/python3.6/site-packages/django/db/models/base.py", line 305, in add_to_class
    value.contribute_to_class(cls, name)
  File "/Library/Frameworks/Python.framework/Versions/3.6/lib/python3.6/site-packages/django/db/models/options.py", line 203, in contribute_to_class
    self.db_table = truncate_name(self.db_table, connection.ops.max_name_length())
  File "/Library/Frameworks/Python.framework/Versions/3.6/lib/python3.6/site-packages/django/db/__init__.py", line 33, in __getattr__
    return getattr(connections[DEFAULT_DB_ALIAS], item)
  File "/Library/Frameworks/Python.framework/Versions/3.6/lib/python3.6/site-packages/django/db/utils.py", line 199, in __getitem__
    self.ensure_defaults(alias)
  File "/Library/Frameworks/Python.framework/Versions/3.6/lib/python3.6/site-packages/django/db/utils.py", line 169, in ensure_defaults
    raise ConnectionDoesNotExist("The connection %s doesn't exist" % alias)
django.db.utils.ConnectionDoesNotExist: The connection default doesn't exist

